Workbook

Sheet Truth snapshot
A1: Truth snapshot
A3: As of | B3: 05 Oct 2026
A4: What this workbook is | B4: The single source of truth for plan status, task status and test evidence. Anything not recorded here is not claimed.
A5: Code state | B5: All implementation is in the uncommitted working tree. Nothing is committed, merged or deployed.
A6: Test run | B6: Backend full suite on SQLite: 3082 passed, 0 failed, 35 skipped. Postgres-only concurrency tests are skipped on SQLite and have not been run since the changes. Web: vitest, tsc -b and ESLint are clean at the last full run.
A7: Plan items | B7: 68 items: 16 Built, 46 Partial, 6 Not built (judged against each item's own scope, from code and tests).
A8: Sign-off | B8: No item is Done. Review is In progress on every Built item: agent review has run, a human has not signed. Decision and external items (host, CA, pharmacist, gateway, devices) are not recorded.
A9: Code review | B9: 69 findings across two rounds: 59 fixed, 8 open, 2 reverted. See the Code review 2026-10-05 sheet.
A10: Freeze | B10: Live NIC e-way, GSTR-2B API, Tally and WhatsApp Cloud stay off. Built items for those are stubs or stored fields only.
A11: Before any deploy | B11: Set PLANWAVE_DATA_KEY and MFA_ENCRYPTION_KEY; run manage.py seal_bank_accounts once; start workers with -Q celery,high_priority,media_heavy,reports; apply migrations (planwave 0004, masters 0030, inventory 0026-0027, core 0051, sales 0063).
A12: Known open items | B12: COD cash receipts on routes, 206AB rates for company vendors, AA consent verification, WhatsApp opt-in source, wall-clock SLA tests, lower-severity web items, Postgres re-run of concurrency tests.

Sheet Founder view
A1: Founder view
A2: Live counts from the task register. A task is verified only when Verification result is Pass. That column is Not run until a test is linked. OS ready stays at zero until all five gates have evidence.
A3: Question | B3: Count | C3: How to read it
A4: Tasks | B4: =COUNTA(TaskRegister[Task ID]) -> 770 | C4: The frozen universe.
A5: MVP (current P0) | B5: =COUNTIF(TaskRegister[Release gate],"MVP") -> 102 | C5: Pilot scope to approve or cut. Release gate is not frozen until you sign it.
A6: Pilot (core P1, RUN or CONTROL) | B6: =COUNTIF(TaskRegister[Release gate],"Pilot") -> 447 | C6: Comes after MVP. This is a rule, not a target of 290.
A7: Later | B7: =COUNTIF(TaskRegister[Release gate],"Later") -> 221 | C7: Hidden from the pilot board. Still in the register.
A8: MVP with a passing test | B8: =COUNTIFS(TaskRegister[Release gate],"MVP",TaskRegister[Verification result],"Pass") -> 40 | C8: Go / no-go numerator. Threshold is a decision, not a formula.
A9: MVP with a test id | B9: =COUNTIFS(TaskRegister[Release gate],"MVP",TaskRegister[Test case ID],"<>") -> 94 | C9: Linked tests that have not been scored as a pass.
A10: Open gaps | B10: =COUNTIF(TaskRegister[Work status],"Gap") -> 92 | C10: Mechanism not found. Do not claim these.
A11: Built, only partly | B11: =COUNTIF(TaskRegister[Work status],"Built - partial") -> 256 | C11: The partial claims.
A12: Tasks with no owner | B12: =COUNTBLANK(TaskRegister[Owner]) -> 770 | C12: Fill owners on MVP rows first.
A13: Tasks with no test id | B13: =COUNTBLANK(TaskRegister[Test case ID]) -> 658 | C13: Validation status does not fill this.
A14: Tasks marked OS ready | B14: =COUNTIF(TaskRegister[OS ready],"Yes") -> 0 | C14: Stays at zero until G1 to G5 each have evidence.
A16: Four-week routine
A17: Week 1. Fill Decision owner and Decision date on P0 gap decisions. Approve or edit Proposed priority, then treat Release gate as frozen.
A18: Week 2. The compliance gaps stay open until someone builds them: admin second factor, a nightly invariant check with an alert, and an audit event test per posting action. This sheet does not mark them done.
A19: Week 3. Add one Test case ID per MVP task, money and stock and tax first. Set Verification result to Pass only when that test passes. Re-run the Postgres concurrency tests; they are still Not verified.
A20: Week 4. Fill Performance SLA actuals from a large-tenant seed, and Customer evidence from one pilot. Competitive targets stay hypotheses until then.
A22: Day to day
A23: Sprint planning | B23: Filter Task Register: Release gate = MVP, Work status = Gap or Built - unverified or Claimed - unverified, sort by Risk score.
A24: Pilot go / no-go | B24: MVP with a passing test, divided by MVP. Pick the threshold in the room. The sheet does not invent 90 percent.
A25: Due diligence | B25: Share P0 gap decisions, Security assurance, and Business integrity. The Not verified labels are the point.
A26: Hiring | B26: Role rollup names the area. Owner on the register names the person.
A27: Release notes | B27: Verification result = Pass. Validation status alone is an author or review label.

Sheet Pilot readiness
A1: Pilot readiness
A2: Three personas only, counted on Persona canonical so every distributor variant is included. Gate counts are MVP tasks with evidence for that gate. G4 and G5 are entered per task on Task Register. OS ready is a formula and needs all five gates.
A3: Persona (canonical) | B3: Tasks | C3: MVP tasks | D3: G1 functional | E3: G2 integrity | F3: G3 resilience and security | G3: G4 user validated | H3: G5 outcome | I3: All five gates (OS ready)
A4: Kirana / Small Retailer | B4: =COUNTIF(TaskRegister[Persona canonical],A4) -> 39 | C4: =COUNTIFS(TaskRegister[Persona canonical],$A4,TaskRegister[Release gate],"MVP") -> 6 | D4: =COUNTIFS(TaskRegister[Persona canonical],$A4,TaskRegister[Release gate],"MVP",TaskRegister[Verification result],"Pass") -> 3 | E4: =COUNTIFS(TaskRegister[Persona canonical],$A4,TaskRegister[Release gate],"MVP",TaskRegister[Integrity evidence],"<>Not verified") -> 0 | F4: =COUNTIFS(TaskRegister[Persona canonical],$A4,TaskRegister[Release gate],"MVP",TaskRegister[Recovery evidence],"<>Not verified",TaskRegister[Security evidence],"<>Not verified",TaskRegister[Concurrency evidence],"<>Not verified") -> 0 | G4: =COUNTIFS(TaskRegister[Persona canonical],$A4,TaskRegister[Release gate],"MVP",TaskRegister[G4 user validated],"Yes") -> 0 | H4: =COUNTIFS(TaskRegister[Persona canonical],$A4,TaskRegister[Release gate],"MVP",TaskRegister[G5 outcome measured],"Yes") -> 0 | I4: =COUNTIFS(TaskRegister[Persona canonical],$A4,TaskRegister[Release gate],"MVP",TaskRegister[OS ready],"Yes") -> 0
A5: Distributor | B5: =COUNTIF(TaskRegister[Persona canonical],A5) -> 37 | C5: =COUNTIFS(TaskRegister[Persona canonical],$A5,TaskRegister[Release gate],"MVP") -> 3 | D5: =COUNTIFS(TaskRegister[Persona canonical],$A5,TaskRegister[Release gate],"MVP",TaskRegister[Verification result],"Pass") -> 1 | E5: =COUNTIFS(TaskRegister[Persona canonical],$A5,TaskRegister[Release gate],"MVP",TaskRegister[Integrity evidence],"<>Not verified") -> 0 | F5: =COUNTIFS(TaskRegister[Persona canonical],$A5,TaskRegister[Release gate],"MVP",TaskRegister[Recovery evidence],"<>Not verified",TaskRegister[Security evidence],"<>Not verified",TaskRegister[Concurrency evidence],"<>Not verified") -> 0 | G5: =COUNTIFS(TaskRegister[Persona canonical],$A5,TaskRegister[Release gate],"MVP",TaskRegister[G4 user validated],"Yes") -> 0 | H5: =COUNTIFS(TaskRegister[Persona canonical],$A5,TaskRegister[Release gate],"MVP",TaskRegister[G5 outcome measured],"Yes") -> 0 | I5: =COUNTIFS(TaskRegister[Persona canonical],$A5,TaskRegister[Release gate],"MVP",TaskRegister[OS ready],"Yes") -> 0
A6: Accountant / Finance | B6: =COUNTIF(TaskRegister[Persona canonical],A6) -> 146 | C6: =COUNTIFS(TaskRegister[Persona canonical],$A6,TaskRegister[Release gate],"MVP") -> 17 | D6: =COUNTIFS(TaskRegister[Persona canonical],$A6,TaskRegister[Release gate],"MVP",TaskRegister[Verification result],"Pass") -> 9 | E6: =COUNTIFS(TaskRegister[Persona canonical],$A6,TaskRegister[Release gate],"MVP",TaskRegister[Integrity evidence],"<>Not verified") -> 0 | F6: =COUNTIFS(TaskRegister[Persona canonical],$A6,TaskRegister[Release gate],"MVP",TaskRegister[Recovery evidence],"<>Not verified",TaskRegister[Security evidence],"<>Not verified",TaskRegister[Concurrency evidence],"<>Not verified") -> 0 | G6: =COUNTIFS(TaskRegister[Persona canonical],$A6,TaskRegister[Release gate],"MVP",TaskRegister[G4 user validated],"Yes") -> 0 | H6: =COUNTIFS(TaskRegister[Persona canonical],$A6,TaskRegister[Release gate],"MVP",TaskRegister[G5 outcome measured],"Yes") -> 0 | I6: =COUNTIFS(TaskRegister[Persona canonical],$A6,TaskRegister[Release gate],"MVP",TaskRegister[OS ready],"Yes") -> 0
A8: Why these three | B8: Kirana owner, distributor, and accountant are the first pilot desks. Other personas stay in the register and are not in this go / no-go.

Sheet P0 gap decisions
A1: Open gap decisions
A2: One row per open or corrected claim, P0 first. Recommended decision is a proposal from the 2026-10-04 review. A decision owner and date must be entered by the founder.
A3: Task ID | B3: Claim | C3: Priority | D3: Status now | E3: Evidence checked | F3: Recommended decision | G3: Needs freeze exception | H3: Target release | I3: Decision | J3: Decision owner | K3: Decision date
A4: P-0115 | B4: Maintain an audit trail | C4: P0 | D4: Partial | E4: Hash chain and append-only guard exist. Coverage of every transaction type is not shown. | F4: Ship the gap: list every posting action, assert each writes an AuditEvent, add one test per action. | G4: Yes - compliance | H4: MVP | I4: Build in MVP (3 days) | J4: Founder (delegated to Claude) | K4: 46299 | L4: Status now (2026-10-05)
A5: X-0432 | B5: Critical transaction to immutable audit trail | C5: P0 | D5: Partial | E5: Same evidence as P-0115. | F5: Ship with P-0115. Close both together. | G5: Yes - compliance | H5: MVP | I5: Build in MVP (with P-0115) | J5: Founder (delegated to Claude) | K5: 46299 | L5: WI-002: Built and tests pass. Human review pending.
A6: P-0507 | B6: MCA Rule 11(g) immutable audit trail | C6: P0 | D6: Partial | E6: Hash chain exists. Rule 11(g) needs an edit log on every accounting record. Mapping not verified. | F6: Have the CA map Rule 11(g) to AuditEvent coverage. Ship any missing edit-log events. | G6: Yes - compliance | H6: MVP | I6: Build in MVP (2 days, CA sign-off) | J6: Founder (delegated to Claude) | K6: 46299 | L6: WI-003: Partial. Missing: Coverage map and certification export exist, but the export does not list the periods logging was on (it returns logging_on=True or refuses). Nothing writes LoggingWindow rows automatically. No edit log (before/after) on every accounting record, only per-action audit events. No test asserts every AUDIT_COVERAGE event is actually emitted.. Human review pending.
A7: S-0561 | B7: Background trial balance zero-sum worker | C7: P0 | D7: Partial | E7: check_invariants management command and trial_balance_balanced exist. No scheduled worker found. | F7: Re-scope to: schedule check_invariants nightly and alert on failure. Do not build a new worker. | G7: Yes - integrity | H7: MVP | I7: Build in MVP (3 days): full worker with quarantine | J7: Founder (delegated to Claude) | K7: 46299 | L7: WI-005: Partial. Missing: No invariant for payment allocations within payment amounts; no registered invariant for ledger output tax equals invoice tax (only a one-off test); AR/AP control vs outstanding only as dashboard-vs-aging projection checks; quarantine block wired to GST soft-close and GSTR export but not to accounting period lock; ops mailbox is only a log line; no test that the nightly run creates the quarantine row end to end; test_plan_s_0561.py absent.. Human review pending.
A8: S-0579 | B8: Cryptographic hash chain on audit trail | C8: P0 | D8: Code Complete & Verified | E8: Built and tested. Sealing is a nightly batch, so recent events sit in a window. | F8: Close as built after confirming the nightly seal is scheduled in production. | G8: No | H8: MVP | I8: Close as built after confirming the nightly seal runs in production, then add a monitoring alert | J8: Founder (delegated to Claude) | K8: 46299 | L8: WI-034: Partial. Missing: No drill log in qos/evidence; the task-level gap path (running seal_audit_chain_task with a stale heartbeat) is not tested directly.. Human review pending.
A9: C-0603 | B9: Section 16(4) time-barring alert and ITC exclusion engine | C9: P0 | D9: Partial | E9: Deadline clock, flags and alert exist and test. No exclusion engine. | F9: Ship the alert as the pilot answer. Defer the exclusion engine to GA unless a pilot customer needs it. | G9: Yes if pulled into pilot | H9: Pilot | I9: Build in MVP (3 days): alert tiers and exclusion engine | J9: Founder (delegated to Claude) | K9: 46299 | L9: WI-017: Partial. Missing: 60 and 7 day warnings only fire when someone POSTs /plan/itc/summary/; no scheduled task; DUE_60/DUE_7 statuses and alert sending are untested; test_plan_c_0603.py absent.. Human review pending.
A10: SEC-0624 | B10: TOTP 2FA for admin roles | C10: P0 | D10: Partial | E10: TOTP, recovery codes and encrypted secrets exist and test. Opt-in only. | F10: Make 2FA mandatory for admin and owner roles. Small change on top of existing code. | G10: Yes - security | H10: MVP | I10: Build in MVP (1.5 days) | J10: Founder (delegated to Claude) | K10: 46299 | L10: WI-010: Built and tests pass. Human review pending.
A11: GOS-0721 | B11: Inbound lead exact-match deduplication | C11: P0 | D11: Code Complete & Verified | E11: Growth OS claim. Name found in code. | F11: Add one end-to-end test and move to Validated. | G11: No | H11: Pilot | I11: Add end-to-end test and validate before Pilot | J11: Founder (delegated to Claude) | K11: 46299 | L11: WI-047: Built and tests pass. Human review pending.
A12: GOS-0737 | B12: Complaint to credit note, return or replacement | C12: P0 | D12: Code Complete & Verified | E12: Growth OS claim. Name found in code. | F12: Add one end-to-end test with stock and ledger check, then validate. | G12: No | H12: Pilot | I12: Add end-to-end test with stock and ledger check, validate before Pilot | J12: Founder (delegated to Claude) | K12: 46299 | L12: WI-048: Partial. Missing: Tests work from draft invoices and assert no stock movement or ledger/journal effect; credit note exactly-once is asserted (second POST returns the same id); test_plan_gos_0737.py absent.. Human review pending.
A13: GOS-0739 | B13: Supplier complaint to purchase debit note | C13: P0 | D13: Code Complete & Verified | E13: Growth OS claim. Name found in code. | F13: Same as GOS-0737. | G13: No | H13: Pilot | I13: Add end-to-end test with stock and ledger check, validate before Pilot | J13: Founder (delegated to Claude) | K13: 46299 | L13: WI-049: Partial. Missing: Complaint to draft debit note flow is tested end to end, but there is no stock-movement or ledger assertion: the note is set COMPLETED by direct save, not through the completion service. backend/tests/test_plan_gos_0739.py does not exist.. Human review pending.
A14: C-0614 | B14: Section 206AB / 206CCA PAN utility check | C14: P1 | D14: Mechanism not found | E14: Not in code. | F14: Defer. Pilot customers verify non-filers manually. Record the risk. | G14: No | H14: GA | I14: Build in GA (3 days): PAN utility check | J14: Founder (delegated to Claude) | K14: 46299 | L14: No plan item maps to this task.
A15: X-0522 | B15: Higher TDS/TCS rate for non-filers | C15: P1 | D15: Mechanism not found | E15: Not in code. Depends on C-0614. | F15: Defer with C-0614. | G15: No | H15: GA | I15: Build in GA (2 days, with C-0614) | J15: Founder (delegated to Claude) | K15: 46299 | L15: No plan item maps to this task.
... A23: UX-0591 | B23: Privacy mask for rupee figures | C23: P3 | D23: Mechanism not found | E23: Not found. | F23: Defer to GA. | G23: No | H23: GA | I23: Build in Pilot (1 day) | J23: Founder (delegated to Claude) | K23: 46299 | L23: WI-057: Partial. Missing: No test; only components using MoneyText are masked, other rupee displays may not be.. Human review pending.

Sheet MVP scope after review
A1: MVP scope after review
A2: MVP tasks that the code review found Partial or absent. Each needs a decision before the pilot: cut it from MVP, build it, or accept and document the limit.
A3: Task ID | B3: Task | C3: Capability class | D3: Work status | E3: Review verdict | F3: What the code shows | G3: Options | H3: Decision | I3: Decision owner | J3: Effort (days) | K3: Why / what quality means | L3: Status now (2026-10-05)
A4: P-0046 | B4: Search medicines while billing | C4: Core | D4: Built - partial | E4: Partial | F4: Product search matches name, SKU, barcode, HSN and custom fields; no native salt/composition or manufacturer field. | G4: Cut from MVP, build, or accept the limit | H4: Build in Pilot | I4: Founder (delegated to Claude) | J4: 2 | K4: Native salt/composition and manufacturer fields, searchable at billing. | L4: WI-036: Partial. Missing: No test searches by salt, composition or manufacturer; no query-budget test within the checkout latency budget.. Human review pending.
A5: P-0052 | B5: Create bulk sales invoices | C5: Core | D5: Built - partial | E5: Partial | F5: Invoices apply price lists and post stock, AR and GST; bulk CSV entry for invoices not found. | G5: Cut from MVP, build, or accept the limit | H5: Build in Pilot | I5: Founder (delegated to Claude) | J5: 4 | K5: Bulk invoice CSV import with validation and per-row errors. | L5: WI-037: Partial. Missing: CSV columns for invoice date and due date, barcode lookup and warehouse are not handled (SKU only, no warehouse or dates). The 2,000-row cap is not tested. Idempotent re-upload is not asserted after a committed run.. Human review pending.
A6: P-0081 | B6: Transfer stock between godowns | C6: Core | D6: Built - partial | E6: Partial | F6: Transfers exist with DRAFT/COMPLETED/CANCELLED only; no dispatch, in-transit, insurance or separate receipt confirmation stages. | G6: Cut from MVP, build, or accept the limit | H6: Build in Pilot | I6: Founder (delegated to Claude) | J6: 6 | K6: Dispatch, in-transit and receipt-confirmation stages for stock transfers. | L6: WI-038: Built and tests pass. Human review pending.
A7: P-0089 | B7: View all shops from one dashboard | C7: Core | D7: Built - partial | E7: Partial | F7: Dashboard shows company-wide totals over all godowns; no outlet switching or per-outlet breakdown found. | G7: Cut from MVP, build, or accept the limit | H7: Build in Pilot | I7: Founder (delegated to Claude) | J7: 5 | K7: Per-outlet breakdown and outlet switching on the dashboard. | L7: WI-039: Partial. Missing: Only an API listing on-hand and reserved stock per warehouse; no web DashboardPage integration or warehouse switching; no query-budget test.. Human review pending.
A8: P-0115 | B8: Maintain an audit trail | C8: Core | D8: Built - partial | E8: Partial | F8: Immutable hash-chained AuditEvent log exists, but it has no IP or before/after value columns and no simple_history; per-transaction coverage is unproven. | G8: Cut from MVP, build, or accept the limit | H8: Build in MVP | I8: Founder (delegated to Claude) | J8: 3 | K8: Audit event on every posting action (journal post, purchase complete with books off included); add IP and before/after values; one test per action; drop the xfail. | L8: WI-001: Built and tests pass. Human review pending.
A9: P-0119 | B9: Identify overdue payments | C9: Core | D9: Built - partial | E9: Partial | F9: Overdue invoices with days_overdue and collection worklist exist; no interest exposure or bad-debt risk calculation. | G9: Cut from MVP, build, or accept the limit | H9: Build in Pilot | I9: Founder (delegated to Claude) | J9: 3 | K9: Interest exposure and bad-debt risk on overdue customers. | L9: WI-040: Built and tests pass. Human review pending.
A10: P-0128 | B10: Approve important business actions | C10: Core | D10: Built - partial | E10: Partial | F10: Owner credit-limit and GST-guard overrides record who and why, but no general pending-approval queue or approve/reject workflow exists. | G10: Cut from MVP, build, or accept the limit | H10: Build in MVP | I10: Founder (delegated to Claude) | J10: 5 | K10: General pending-approval queue with approve and reject and an audit trail. | L10: WI-025: Partial. Missing: The approval queue is enforced only for invoice cancel and large stock adjustment; not wired for credit-limit override (separate unlock), invoice amend, discount, returns/credit notes, backdating/period reopen, supplier payment, write-off or bulk import commit; no per-action configurable approver; no web UI.. Human review pending.
A11: P-0152 | B11: Adjust stock with authorization | C11: Core | D11: Built - partial | E11: Partial | F11: Adjustment needs a mandatory reason and inventory-manage permission and posts ADJUSTMENT; no dual-approval workflow. | G11: Cut from MVP, build, or accept the limit | H11: Build in MVP | I11: Founder (delegated to Claude) | J11: 2 | K11: Dual approval for stock adjustments above a threshold, on the approval queue. | L11: WI-026: Built and tests pass. Human review pending.
A12: P-0180 | B12: Configure branches/godowns | C12: Core | D12: Built - partial | E12: Partial | F12: Warehouse has name, code, address and default flag; no contact fields or user-to-location mapping. | G12: Cut from MVP, build, or accept the limit | H12: Build in Pilot | I12: Founder (delegated to Claude) | J12: 2 | K12: Contact fields and user-to-location mapping on warehouses. | L12: WI-041: Partial. Missing: Contact name and phone are blank=True (not required); the user-to-warehouse mapping is stored but nothing enforces or reads it; no test covers the mapping or the default rule.. Human review pending.
A13: X-0432 | B13: Critical transaction → immutable audit trail exists | C13: Core | D13: Built - partial | E13: Partial | F13: AuditEvent is hash-chained and guarded against update/delete, but coverage of every critical transaction is not shown and SimpleHistory is not used. | G13: Cut from MVP, build, or accept the limit | H13: Build in MVP | I13: Founder (delegated to Claude) | J13: 0 | K13: Delivered with P-0115. | L13: WI-002: Built and tests pass. Human review pending.
A14: P-0503 | B14: Audit 2A/2B vs Books reconciliation and verify eligible vs blocked ITC | C14: Core | D14: Built - partial | E14: Partial | F14: 2B matching and eligible/ineligible flags exist, but no Section 17(5) blocked-credit classification. | G14: Cut from MVP, build, or accept the limit | H14: Build in MVP | I14: Founder (delegated to Claude) | J14: 3 | K14: Section 17(5) blocked-credit classification in the 2A/2B reconciliation. | L14: WI-019: Partial. Missing: Blocked-credit classification is not added to the existing reporting/gstr2b.py reconciliation of uploaded 2B files; it only scores caller-supplied rows via /plan/gstr2b/score/ with a caller-supplied blocked_credit flag.. Human review pending.
A15: P-0507 | B15: Audit MCA mandated immutable audit trail (Rule 11(g) Companies Audit Rules) | C15: Core | D15: Built - partial | E15: Partial | F15: Hash-chained audit events with verify exist; not django-simple-history, and no certification report or Rule 11(g) coverage of all records. | G15: Cut from MVP, build, or accept the limit | H15: Build in MVP | I15: Founder (delegated to Claude) | J15: 2 | K15: Rule 11(g) coverage map signed off by the CA, edit log on every accounting record, certification export. | L15: WI-003: Partial. Missing: Coverage map and certification export exist, but the export does not list the periods logging was on (it returns logging_on=True or refuses). Nothing writes LoggingWindow rows automatically. No edit log (before/after) on every accounting record, only per-action audit events. No test asserts every AUDIT_COVERAGE event is actually emitted.. Human review pending.
... A49: X-0715 | B49: Customer changes legal name and registered address: system updates master while preserving historical invoices | C49: Core | D49: Built - partial | E49: Partial | F49: Only GSTIN and place of supply are frozen at completion; customer name and address are read live so history can change. | G49: Cut from MVP, build, or accept the limit | H49: Build in MVP | I49: Founder (delegated to Claude) | J49: 2 | K49: Snapshot customer name and address on the invoice at completion; backfill existing invoices. | L49: WI-014: Partial. Missing: Backfill copies current master data and does not use the audit-history name as of the invoice date; snapshot tests cover sales invoices only, not credit/debit notes or purchase bills.. Human review pending.

Sheet Plan guide
A1: Implementation plan: guide
A2: How the plan is built, what each column means and how to keep it current.
A4: Plan start (Monday) | B4: 46307
A5: Agent lanes assumed | B5: 2
A6: Contingency buffer | B6: 0.2
A7: Working days per week | B7: 5
A10: What this is | B10: One row per piece of work for the quality-first decisions of 2026-10-04. Revised after the 63 pre-implementation questions: see the Plan decisions sheet for every answer and what it changed. Each row has five stages (Design, Build, Tests, Review, Register sync); Status, percent done, days late and RAG are formulas driven by the stage cells and actual dates.
A11: Team assumption | B11: One human owner plus agents (default; confirm). Two agent lanes run in parallel only on independent items, each in its own git worktree and Postgres database. Decisions and external reviews sit outside the lanes. Change LANES in build_plan.py if the real team is different.
A12: Dates | B12: Scheduled for the lanes above, Monday to Friday, skipping these holidays: 20 Oct 2026, 09 Nov 2026, 11 Nov 2026, 24 Nov 2026, 25 Dec 2026, 26 Jan 2027. Each estimate carries a 20% buffer, each dependency leaves one clear day for review, and each milestone adds one week before it is called. Dates are fixed text; re-run qos/evidence/build_plan.py to reschedule.
A13: Waves | B13: Wave 1 = Build in MVP, wave 2 = Build in Pilot, wave 3 = Build in GA. Every wave 2 item depends on VER-1 and every wave 3 item on VER-2, so a later wave never starts before the earlier gate closes.
A14: Freeze | B14: The plan does not override docs/FREEZE_SCOPE.md. Live NIC e-way, GSTR-2B API, Tally and WhatsApp Cloud stay behind their flags, default off, and are built against fakes and offline inputs. Flipping a flag is a separate freeze exception.
A15: What you edit | B15: Only the cream cells: Owner, the five stage cells, Actual start, Actual done, Blocked reason, PR / branch and Evidence.
A16: Stage values | B16: Not started, In progress, Done, Blocked, N/A. Use N/A when a stage does not apply.
A17: Definition of done | B17: An item is Done when all five stages are Done or N/A. What each stage means depends on the item's Kind (column AG): see the Acceptance criteria column, which states the item's own pass condition, its rejecting case and the done rule for its kind. Features: tests for the touched apps on Postgres, lint and types clean, register_sync scores the test. Web: Vitest or Playwright, tsc -b, ESLint, accessibility check. Performance: benchmark job report. Drill: recorded timings. Decision and external: recorded decision or written sign-off. Gate: checklist.
A18: Reviewer rule | B18: The author never signs their own Review. Agent-built work gets an agent code-review pass, then the human signs. Human-built work gets an agent review, then the human signs after a day. Compliance items also need the CA; pharmacy items a licensed pharmacist.
A19: When tests run | B19: Each pull request: tests for the touched apps plus lint and type checks. Full backend suite on Postgres: nightly and at each verification gate. Performance and load tests: their own scheduled job, never in the pull-request run.
A20: Source of truth | B20: Bizboard_Product_Task_Universe_Master.xlsx is the source of truth and the file register_sync.py updates. Bizboard_Master_Task_Register_Enhanced.xlsx is a mirror written by recalc_xlsx.ps1 -Mirror. Archives are read-only.
A21: Other plans | B21: Production bugs jump the queue, capped at 20% of capacity, and each interrupt is logged in Plan change log. This plan preempts the bug-remediation, UX, FMEA and ISO 25010 plans for new work; items there that duplicate a work item here are merged into it.
... A25: Weekly routine | B25: Monday: set stages and actual dates, record blockers, rerun register_sync.py after a test run, recalculate the workbook (qos/tools/recalc_xlsx.ps1), review Plan rollup and Plan by week, and log any date or scope change in Plan change log.

Sheet Plan decisions
A1: Plan decisions: the 63 pre-implementation questions
A2: Status: Decided = settled here; Confirm = default chosen, founder confirms before the item starts; External = needs a CA, pharmacist, host or other outside input; Dropped = removed from the plan.
A4: Q | B4: Topic | C4: Items | D4: Status | E4: Answer | F4: What changed in the plan | G4: Founder confirmed (date)
A5: 1 | B5: Team and parallelism | C5: All | D5: Confirm | E5: Plan for one human owner plus agents. Two agent lanes run in parallel only on independent items, each in its own git worktree and its own Postgres database. The human decides, reviews and signs. Start moves to Monday 12 Oct 2026, not 5 Oct. If the real team is larger, change DEVS in build_plan.py and regenerate. | F5: Developers 3 to 2 lanes; start 12 Oct; owners Agent 1, Agent 2, Human reviewer.
A6: 2 | B6: Feature freeze | C6: WI-027, 029-032, 060, 061 | D6: Decided | E6: The plan does not override the freeze. Everything touching live NIC, GSTR-2B API, Tally and WhatsApp Cloud is built behind its existing flag, default off, against a fake adapter and offline inputs. Flipping a flag is a separate freeze exception and is not part of any item. WI-027 becomes an in-app token; WI-029-031 become stub actions plus stored fields; WI-032 computes validity from entered distance only; PIN-to-PIN lookup is deferred. | F6: Scope of WI-027, 029, 030, 031, 032, 060, 061 rewritten; flags stay off.
A7: 3 | B7: Second reviewer | C7: All | D7: Confirm | E7: Rule: the author never signs their own Review. Agent-built work gets an agent code-review pass first, then the human signs. Human-built work gets an agent review, then the human signs after a day's gap. Compliance items also need the CA, pharmacy items a licensed pharmacist. If you want a named human second reviewer, add them as Owner on the Review stage. | F7: Definition of done: reviewer rule added to Plan guide.
A8: 4 | B8: Source-of-truth workbook | C8: All | D8: Decided | E8: Bizboard_Product_Task_Universe_Master.xlsx is the source of truth and the file register_sync.py updates by default. Bizboard_Master_Task_Register_Enhanced.xlsx is a mirror written by recalc_xlsx.ps1 -Mirror. Archives are read-only. The _UPDATED file is renamed over the Master once Excel releases it. | F8: Plan guide states the rule.
A9: 5 | B9: Other open plans | C9: All | D9: Decided | E9: Production bugs jump the queue, capped at 20% of capacity, and each interrupt is logged in the change log. This plan preempts the bug-remediation, UX, FMEA and ISO 25010 plans for new work, but any item in those plans that duplicates a work item here is merged into it rather than done twice. | F9: 20% interrupt allowance noted in Plan guide.
A10: 6 | B10: Postgres host and backup keys | C10: WI-007 | D10: External | E10: Recommended default: managed Postgres in an India region with built-in point-in-time recovery, RPO 5 minutes, RTO 1 hour for the pilot. Backup encryption keys live in the provider's key service, administered by the founder, with a sealed break-glass copy held separately. WI-007 cannot be designed until you pick the provider, so a new decision item DEC-HOST comes first and WI-007 depends on it. | F10: New item DEC-HOST (owner Founder); WI-007 depends on it.
A11: 7 | B11: Chartered accountant for Rule 11(g) | C11: WI-003, 004 | D11: External | E11: Build the coverage map now and sign later. A new external item CA-SIGN follows WI-003. If no CA is named by 2 Nov 2026, M1 still closes technically but is marked 'pilot with documented residual: Rule 11(g) sign-off pending'. The same CA reviews the tax rule tables in WI-016 to WI-020, so a new item DEC-CA (engage the CA) precedes them. | F11: New items DEC-CA and CA-SIGN.
A12: 8 | B12: Item-specific pass conditions | C12: All | D12: Decided | E12: Every item now has its own pass condition and rejecting case, written in the plan, and the definition of done depends on the item's kind: feature, web, performance, infrastructure drill, decision or process gate. The four pasted lines are gone. | F12: Acceptance criteria rewritten per item; new Kind column.
A13: 9 | B13: Frontend tests and register sync | C13: WI-043, 052-057 | D13: Decided | E13: Web items are done on Vitest component tests, a Playwright flow where there is a flow, tsc -b, ESLint with zero errors and an accessibility check. They do not need the backend suite. register_sync.py is extended to read Vitest and Playwright JUnit output (new item REG-WEB, first in the plan), and web test references become real file paths. | F13: New item REG-WEB; web items depend on it; test globs replaced with files.
A14: 10 | B14: WI-002 and WI-004 | C14: WI-002, 004 | D14: Decided | E14: Yes. Their remaining work is Review plus the register update. Evidence is the parent item's tests (WI-001 and WI-003). Design, Build and Tests stay N/A. | F14: Done condition for these items: parent Done and register row updated.
A15: 11 | B15: Items with no register task | C15: WI-033, 035, 058, 067 | D15: Decided | E15: Verification gates have no register row and are done when their checklist passes. WI-033 gets a new register row (next free X- number) created when the item starts, so it can be scored. | F15: Done condition by kind; WI-033 gets a register row at start.
A16: 12 | B16: Test file for SEC-0624 | C16: WI-010 | D16: Decided | E16: The existing test_mfa.py stays as the regression base. A new test_mfa_mandatory.py covers enforcement and first-login enrolment. The strict xfail test in test_register_integrity_gaps.py becomes a normal passing test. WI-005 keeps test_register_integrity_gaps.py for the invariant tests only. | F16: Planned test files corrected.
... A67: 63 | B67: Section 171 anti-profiteering | C67: WI-066 | D67: Dropped | E67: Dropped from the plan, kept in the register as On request, because enforcement has been wound down as far as I know. CA to confirm. If it comes back: count rate-cut notifications as events, with the last price before the cut as the baseline. | F67: WI-066 removed.

Sheet Implementation plan
A1: Implementation plan
A2: One row per work item. Cream cells are inputs; everything else is a formula or fixed plan text. Filter on Wave, Owner, Status, RAG or Kind.
A4: WI ID | B4: Register task | C4: Work item | D4: Wave | E4: Release gate | F4: Workstream | G4: Layer | H4: Scope (quality-first) | I4: Acceptance criteria | J4: Planned test file | K4: Depends on | L4: Owner | M4: Estimate (days) | N4: Planned days (with buffer) | O4: Planned start | P4: Planned due | Q4: Design | R4: Build | S4: Tests | T4: Review | U4: Register sync | V4: Status | W4: % done | X4: Actual start | Y4: Actual done | Z4: Days late | AA4: RAG | AB4: Blocked reason | AC4: PR / branch | AD4: Evidence (test ids, run id) | AE4: Register work status | AF4: Register verification | AG4: Kind | AH4: Cut line | AI4: Decision refs (Q) | AJ4: Plan key
A5: WI-068 | C5: Extend register_sync.py to score Vitest and Playwright results | D5: 1 | E5: MVP | F5: Platform & reliability | G5: Tooling | H5: Parse Vitest and Playwright JUnit, map web test file paths to register rows, unit-test the parser against real output. | I5: Pass: register_sync.py scores Vitest and Playwright results onto register rows. Rejecting case: A web test that fails marks its row Fail; an unknown path is reported as unmatched. Done means: the tool runs on real output from the suites, its parser has unit tests, and the reviewer signs. | J5: qos/tools/tests/test_register_sync_web.py | L5: Agent 1 | M5: 1 | N5: =ROUNDUP(M5*(1+'Plan guide'!$B$6),0) -> 2 | O5: 46307 | P5: 46308 | Q5: Done | R5: Done | S5: In progress | T5: In progress | U5: Not started | V5: =IF(COUNTIF(Q5:U5,"Blocked")>0,"Blocked",IF(COUNTIF(Q5:U5,"Done")+COUNTIF(Q5:U5,"N/A")=5,"Done",IF(COUNTIF(Q5:U5,"Done")+COUNTIF(Q5:U5,"In progress")>0,"In progress","Not started"))) -> In progress | W5: =IF(5-COUNTIF(Q5:U5,"N/A")=0,1,COUNTIF(Q5:U5,"Done")/(5-COUNTIF(Q5:U5,"N/A"))) -> 0.4 | Z5: =IF(V5="Done",IF(Y5="",0,MAX(0,Y5-P5)),MAX(0,TODAY()-P5)) -> 0 | AA5: =IF(V5="Done","Done",IF(V5="Blocked","Red",IF(Z5>0,"Red",IF(AND(O5<=TODAY(),P5-TODAY()<=3,W5<0.5),"Amber","Green")))) -> Green | AB5: Agent review done; human sign-off pending | AC5: uncommitted working tree | AD5: Tests: qos/tools/tests/test_register_sync_web.py::test_parser_reads_pytest_vitest_and_playwright [not in run]; qos/tools/tests/test_register_sync_web.py::test_failed_web_test_marks_the_row_fail_and_unknown_path_is_unmatched [not in run] | Code: qos/tools/register_sync.py:load_junit; qos/tools/register_sync.py:merge_junit | Run: pytest on SQLite 2026-10-05 (Postgres-only tests skipped) | AG5: tooling | AI5: 9 | AJ5: REG-WEB
A6: WI-069 | C6: Decide Postgres host, RPO/RTO and backup-key custody | D6: 1 | E6: MVP | F6: Platform & reliability | G6: Process | H6: Founder chooses the provider (default: managed Postgres in an India region with point-in-time recovery), confirms RPO 5 min and RTO 1 h, and names the key administrator. | I6: Pass: Provider, RPO, RTO and key administrator recorded. Rejecting case: S-0570 does not start until this is recorded. Done means: the decision is recorded in the Plan decisions sheet with date and owner. | L6: Founder | M6: 0.5 | N6: =ROUNDUP(M6*(1+'Plan guide'!$B$6),0) -> 1 | O6: 46307 | P6: 46307 | Q6: Not started | R6: N/A | S6: N/A | T6: Not started | U6: N/A | V6: =IF(COUNTIF(Q6:U6,"Blocked")>0,"Blocked",IF(COUNTIF(Q6:U6,"Done")+COUNTIF(Q6:U6,"N/A")=5,"Done",IF(COUNTIF(Q6:U6,"Done")+COUNTIF(Q6:U6,"In progress")>0,"In progress","Not started"))) -> Not started | W6: =IF(5-COUNTIF(Q6:U6,"N/A")=0,1,COUNTIF(Q6:U6,"Done")/(5-COUNTIF(Q6:U6,"N/A"))) -> 0 | Z6: =IF(V6="Done",IF(Y6="",0,MAX(0,Y6-P6)),MAX(0,TODAY()-P6)) -> 0 | AA6: =IF(V6="Done","Done",IF(V6="Blocked","Red",IF(Z6>0,"Red",IF(AND(O6<=TODAY(),P6-TODAY()<=3,W6<0.5),"Amber","Green")))) -> Green | AB6: Gap: No file records the provider choice, RPO 5 min / RTO 1 h confirmation or key administrator; the plan only states a recommended default. | AC6: uncommitted working tree | AD6: Run: pytest on SQLite 2026-10-05 (Postgres-only tests skipped) | AG6: decision | AI6: 6 | AJ6: DEC-HOST
A7: WI-070 | C7: Engage a chartered accountant for Rule 11(g) and the tax rule tables | D7: 1 | E7: MVP | F7: GST & compliance | G7: Process | H7: Name the CA and agree the review scope: Rule 11(g) coverage, s.16(2), s.16(4), s.17(5), s.50 tables, e-way validity slabs, bad-debt buckets. | I7: Pass: CA named and review scope agreed in writing. Rejecting case: Tax rule items do not close without CA review. Done means: the decision is recorded in the Plan decisions sheet with date and owner. | L7: Founder | M7: 0.5 | N7: =ROUNDUP(M7*(1+'Plan guide'!$B$6),0) -> 1 | O7: 46307 | P7: 46307 | Q7: Not started | R7: N/A | S7: N/A | T7: Not started | U7: N/A | V7: =IF(COUNTIF(Q7:U7,"Blocked")>0,"Blocked",IF(COUNTIF(Q7:U7,"Done")+COUNTIF(Q7:U7,"N/A")=5,"Done",IF(COUNTIF(Q7:U7,"Done")+COUNTIF(Q7:U7,"In progress")>0,"In progress","Not started"))) -> Not started | W7: =IF(5-COUNTIF(Q7:U7,"N/A")=0,1,COUNTIF(Q7:U7,"Done")/(5-COUNTIF(Q7:U7,"N/A"))) -> 0 | Z7: =IF(V7="Done",IF(Y7="",0,MAX(0,Y7-P7)),MAX(0,TODAY()-P7)) -> 0 | AA7: =IF(V7="Done","Done",IF(V7="Blocked","Red",IF(Z7>0,"Red",IF(AND(O7<=TODAY(),P7-TODAY()<=3,W7<0.5),"Amber","Green")))) -> Green | AB7: Gap: No file records a named CA or an agreed review scope. | AC7: uncommitted working tree | AD7: Run: pytest on SQLite 2026-10-05 (Postgres-only tests skipped) | AG7: decision | AI7: 7 | AJ7: DEC-CA
A8: WI-001 | B8: P-0115 | C8: Maintain an audit trail | D8: 1 | E8: MVP | F8: Audit & integrity | G8: Backend | H8: Audit event with actor, IP and before/after values on: sales invoice complete, cancel, amend; sales return; credit and debit notes; purchase invoice complete (books on and off); purchase return; customer receipt; supplier payment; journal post and reverse; stock adjustment, transfer, goods receipt; payroll finalise; period lock and reopen. One test per action; remove the xfails. | I8: Pass: Every action in the scope list writes exactly one AuditEvent with actor, IP and before/after; the chain verifies. Rejecting case: A journal post or a purchase complete with books off that writes no event fails its test (the current xfails); a tampered event fails verification. Done means: tests for the touched apps pass on Postgres 17 with lint and type checks clean and any strict xfail for the item removed; the reviewer (not the author) signs; register_sync.py scores the test and the register row reads Built - tested / Pass; the full suite runs nightly and at the wave gate. | J8: backend/tests/test_register_audit_coverage.py | L8: Agent 2 | M8: 3 | N8: =ROUNDUP(M8*(1+'Plan guide'!$B$6),0) -> 4 | O8: 46307 | P8: 46310 | Q8: Done | R8: Done | S8: Done | T8: In progress | U8: Done | V8: =IF(COUNTIF(Q8:U8,"Blocked")>0,"Blocked",IF(COUNTIF(Q8:U8,"Done")+COUNTIF(Q8:U8,"N/A")=5,"Done",IF(COUNTIF(Q8:U8,"Done")+COUNTIF(Q8:U8,"In progress")>0,"In progress","Not started"))) -> In progress | W8: =IF(5-COUNTIF(Q8:U8,"N/A")=0,1,COUNTIF(Q8:U8,"Done")/(5-COUNTIF(Q8:U8,"N/A"))) -> 0.8 | Z8: =IF(V8="Done",IF(Y8="",0,MAX(0,Y8-P8)),MAX(0,TODAY()-P8)) -> 0 | AA8: =IF(V8="Done","Done",IF(V8="Blocked","Red",IF(Z8>0,"Red",IF(AND(O8<=TODAY(),P8-TODAY()<=3,W8<0.5),"Amber","Green")))) -> Green | AB8: Agent review done; human sign-off pending | AC8: uncommitted working tree | AD8: Tests: tests/test_register_audit_coverage.py::test_sales_invoice_complete_writes_audit_event [pass]; tests/test_plan_above_items.py::test_period_lock_and_reopen_name_the_actor [pass]; tests/test_plan_above_items.py::test_payroll_finalise_writes_an_audit_event [pass]; tests/test_plan_above_items.py::test_amended_invoice_uses_the_coverage_event_name [pass] | Code: backend/core/services/audit.py:before_status_for_event; backend/planwave/services.py:AUDIT_COVERAGE | Run: pytest on SQLite 2026-10-05 (Postgres-only tests skipped) | AE8: =IFERROR(INDEX('Task Register'!$AJ$2:$AJ$771,MATCH(B8,'Task Register'!$A$2:$A$771,0)),"") -> Built - tested | AF8: =IFERROR(INDEX('Task Register'!$AU$2:$AU$771,MATCH(B8,'Task Register'!$A$2:$A$771,0)),"") -> Pass | AG8: feature | AI8: 19 | AJ8: P-0115
A9: WI-002 | B9: X-0432 | C9: Critical transaction → immutable audit trail exists | D9: 1 | E9: MVP | F9: Audit & integrity | G9: Backend | H9: Delivered with P-0115. | I9: Pass: Parent P-0115 is Done and its tests pass. Rejecting case: Same rejecting cases as P-0115. Done means: tests for the touched apps pass on Postgres 17 with lint and type checks clean and any strict xfail for the item removed; the reviewer (not the author) signs; register_sync.py scores the test and the register row reads Built - tested / Pass; the full suite runs nightly and at the wave gate. | J9: backend/tests/test_register_audit_coverage.py | K9: WI-001 | L9: Agent 2 | M9: 0 | N9: =ROUNDUP(M9*(1+'Plan guide'!$B$6),0) -> 0 | O9: 46314 | P9: 46314 | Q9: N/A | R9: N/A | S9: N/A | T9: In progress | U9: Done | V9: =IF(COUNTIF(Q9:U9,"Blocked")>0,"Blocked",IF(COUNTIF(Q9:U9,"Done")+COUNTIF(Q9:U9,"N/A")=5,"Done",IF(COUNTIF(Q9:U9,"Done")+COUNTIF(Q9:U9,"In progress")>0,"In progress","Not started"))) -> In progress | W9: =IF(5-COUNTIF(Q9:U9,"N/A")=0,1,COUNTIF(Q9:U9,"Done")/(5-COUNTIF(Q9:U9,"N/A"))) -> 0.5 | Z9: =IF(V9="Done",IF(Y9="",0,MAX(0,Y9-P9)),MAX(0,TODAY()-P9)) -> 0 | AA9: =IF(V9="Done","Done",IF(V9="Blocked","Red",IF(Z9>0,"Red",IF(AND(O9<=TODAY(),P9-TODAY()<=3,W9<0.5),"Amber","Green")))) -> Green | AB9: Agent review done; human sign-off pending | AC9: uncommitted working tree | AD9: Tests: tests/test_register_audit_coverage.py::test_sales_invoice_complete_writes_audit_event [pass]; tests/test_register_audit_coverage.py::test_supplier_payment_post_writes_audit_event [pass]; tests/test_register_audit_coverage.py::test_stock_adjustment_writes_audit_event [pass]; tests/test_audit_append_only.py::test_saving_an_existing_event_is_refused [pass] | Code: backend/core/services/audit.py:record_document_event; backend/planwave/services.py:AUDIT_COVERAGE | Run: pytest on SQLite 2026-10-05 (Postgres-only tests skipped) | AE9: =IFERROR(INDEX('Task Register'!$AJ$2:$AJ$771,MATCH(B9,'Task Register'!$A$2:$A$771,0)),"") -> Built - tested | AF9: =IFERROR(INDEX('Task Register'!$AU$2:$AU$771,MATCH(B9,'Task Register'!$A$2:$A$771,0)),"") -> Pass | AG9: feature | AI9: 10 | AJ9: X-0432
A10: WI-003 | B10: P-0507 | C10: Audit MCA mandated immutable audit trail (Rule 11(g) Companies Audit Rules) | D10: 1 | E10: MVP | F10: Audit & integrity | G10: Backend | H10: Rule 11(g) coverage map (action to audit event) built now; edit log on every accounting record; certification export listing the periods in which logging was on. CA sign-off is the separate CA-SIGN item. | I10: Pass: Coverage map lists every accounting record with its event; certification export shows logging on for the whole year. Rejecting case: Export refuses to certify when the chain has a gap or logging was off in a period. Done means: tests for the touched apps pass on Postgres 17 with lint and type checks clean and any strict xfail for the item removed; the reviewer (not the author) signs; register_sync.py scores the test and the register row reads Built - tested / Pass; the full suite runs nightly and at the wave gate. | J10: backend/tests/test_plan_p_0507.py | K10: WI-001 | L10: Agent 1 | M10: 2 | N10: =ROUNDUP(M10*(1+'Plan guide'!$B$6),0) -> 3 | O10: 46314 | P10: 46317 | Q10: Done | R10: In progress | S10: In progress | T10: Not started | U10: Not started | V10: =IF(COUNTIF(Q10:U10,"Blocked")>0,"Blocked",IF(COUNTIF(Q10:U10,"Done")+COUNTIF(Q10:U10,"N/A")=5,"Done",IF(COUNTIF(Q10:U10,"Done")+COUNTIF(Q10:U10,"In progress")>0,"In progress","Not started"))) -> In progress | W10: =IF(5-COUNTIF(Q10:U10,"N/A")=0,1,COUNTIF(Q10:U10,"Done")/(5-COUNTIF(Q10:U10,"N/A"))) -> 0.2 | Z10: =IF(V10="Done",IF(Y10="",0,MAX(0,Y10-P10)),MAX(0,TODAY()-P10)) -> 0 | AA10: =IF(V10="Done","Done",IF(V10="Blocked","Red",IF(Z10>0,"Red",IF(AND(O10<=TODAY(),P10-TODAY()<=3,W10<0.5),"Amber","Green")))) -> Green | AB10: Gap: Coverage map and certification export exist, but the export does not list the periods logging was on (it returns logging_on=True or refuses). Nothing writes LoggingWindow rows automatically. No edit log (before/after) on every accounting record, only per-action audit events. No test asserts every AUDIT_COVERAGE event is actually emitted. | AC10: uncommitted working tree | AD10: Tests: tests/test_planwave_remaining.py::test_certification_refuses_a_dark_window [pass]; tests/test_register_audit_coverage.py::test_sales_invoice_complete_writes_audit_event [pass]; tests/test_plan_above_items.py::test_period_lock_and_reopen_name_the_actor [pass] | Code: backend/planwave/services.py:certification_export; backend/planwave/services.py:AUDIT_COVERAGE; backend/planwave/models.py:LoggingWindow; backend/planwave/views.py:CertificationView | Run: pytest on SQLite 2026-10-05 (Postgres-only tests skipped) | AE10: =IFERROR(INDEX('Task Register'!$AJ$2:$AJ$771,MATCH(B10,'Task Register'!$A$2:$A$771,0)),"") -> Built - partial | AF10: =IFERROR(INDEX('Task Register'!$AU$2:$AU$771,MATCH(B10,'Task Register'!$A$2:$A$771,0)),"") -> Partial | AG10: feature | AI10: 7, 10 | AJ10: P-0507
A11: WI-004 | B11: C-0616 | C11: Companies (Accounts) Rules Rule 3(1) and Rule 11(g) audit trail compliance certification | D11: 1 | E11: MVP | F11: Audit & integrity | G11: Backend | H11: Delivered with P-0507: report certifying logging was never disabled. | I11: Pass: Report certifies logging was never disabled for the financial year. Rejecting case: Report flags any window in which logging was disabled. Done means: tests for the touched apps pass on Postgres 17 with lint and type checks clean and any strict xfail for the item removed; the reviewer (not the author) signs; register_sync.py scores the test and the register row reads Built - tested / Pass; the full suite runs nightly and at the wave gate. | J11: backend/tests/test_plan_c_0616.py | K11: WI-003 | L11: Agent 1 | M11: 0 | N11: =ROUNDUP(M11*(1+'Plan guide'!$B$6),0) -> 0 | O11: 46321 | P11: 46321 | Q11: N/A | R11: N/A | S11: N/A | T11: In progress | U11: Done | V11: =IF(COUNTIF(Q11:U11,"Blocked")>0,"Blocked",IF(COUNTIF(Q11:U11,"Done")+COUNTIF(Q11:U11,"N/A")=5,"Done",IF(COUNTIF(Q11:U11,"Done")+COUNTIF(Q11:U11,"In progress")>0,"In progress","Not started"))) -> In progress | W11: =IF(5-COUNTIF(Q11:U11,"N/A")=0,1,COUNTIF(Q11:U11,"Done")/(5-COUNTIF(Q11:U11,"N/A"))) -> 0.5 | Z11: =IF(V11="Done",IF(Y11="",0,MAX(0,Y11-P11)),MAX(0,TODAY()-P11)) -> 0 | AA11: =IF(V11="Done","Done",IF(V11="Blocked","Red",IF(Z11>0,"Red",IF(AND(O11<=TODAY(),P11-TODAY()<=3,W11<0.5),"Amber","Green")))) -> Green | AB11: Agent review done; human sign-off pending | AC11: uncommitted working tree | AD11: Tests: tests/test_planwave_remaining.py::test_certification_refuses_a_dark_window [pass] | Code: backend/planwave/services.py:certification_export; backend/planwave/views.py:CertificationView; backend/planwave/models.py:LoggingWindow | Run: pytest on SQLite 2026-10-05 (Postgres-only tests skipped) | AE11: =IFERROR(INDEX('Task Register'!$AJ$2:$AJ$771,MATCH(B11,'Task Register'!$A$2:$A$771,0)),"") -> Built - tested | AF11: =IFERROR(INDEX('Task Register'!$AU$2:$AU$771,MATCH(B11,'Task Register'!$A$2:$A$771,0)),"") -> Pass | AG11: feature | AJ11: C-0616
A12: WI-005 | B12: S-0561 | C12: Automated background trial balance zero-sum verification worker | D12: 1 | E12: MVP | F12: Audit & integrity | G12: Backend | H12: Nightly worker runs these invariants: trial balance zero; every journal balanced; AR/AP control accounts equal customer/supplier outstanding; stock ledger equals movements; allocations within payments; ledger output tax equals invoice tax. A violation creates a quarantine record, blocks period close and GST export until cleared (billing continues), and alerts Owner, Accountant and the ops mailbox. | I12: Pass: Nightly task runs every listed invariant; a violation creates a quarantine record, blocks period close and GST export and alerts. Rejecting case: An unbalanced journal inserted through the ORM is caught on the next run and blocks period close. Done means: tests for the touched apps pass on Postgres 17 with lint and type checks clean and any strict xfail for the item removed; the reviewer (not the author) signs; register_sync.py scores the test and the register row reads Built - tested / Pass; the full suite runs nightly and at the wave gate. | J12: backend/tests/test_plan_s_0561.py; backend/tests/test_register_integrity_gaps.py (invariant tests) | L12: Agent 2 | M12: 3 | N12: =ROUNDUP(M12*(1+'Plan guide'!$B$6),0) -> 4 | O12: 46311 | P12: 46317 | Q12: Done | R12: In progress | S12: In progress | T12: Not started | U12: Not started | V12: =IF(COUNTIF(Q12:U12,"Blocked")>0,"Blocked",IF(COUNTIF(Q12:U12,"Done")+COUNTIF(Q12:U12,"N/A")=5,"Done",IF(COUNTIF(Q12:U12,"Done")+COUNTIF(Q12:U12,"In progress")>0,"In progress","Not started"))) -> In progress | W12: =IF(5-COUNTIF(Q12:U12,"N/A")=0,1,COUNTIF(Q12:U12,"Done")/(5-COUNTIF(Q12:U12,"N/A"))) -> 0.2 | Z12: =IF(V12="Done",IF(Y12="",0,MAX(0,Y12-P12)),MAX(0,TODAY()-P12)) -> 0 | AA12: =IF(V12="Done","Done",IF(V12="Blocked","Red",IF(Z12>0,"Red",IF(AND(O12<=TODAY(),P12-TODAY()<=3,W12<0.5),"Amber","Green")))) -> Green | AB12: Gap: No invariant for payment allocations within payment amounts; no registered invariant for ledger output tax equals invoice tax (only a one-off test); AR/AP control vs outstanding only as dashboard-vs-aging projection checks; quarantine block wired to GST soft-close and GSTR export but not to accounting period lock; ops mailbox is only a log line; no test that the nightly run creates the quarantine row end to end; test_plan_s_0561.py absent. | AC12: uncommitted working tree | AD12: Tests: tests/test_planwave_remaining.py::test_quarantine_blocks_close_and_clears [pass]; tests/test_code_review_2026_10_05.py::test_one_open_quarantine_row_per_company [pass]; tests/test_fmea_mitigations.py::test_tc_fmea_010_a_failed_invariant_notifies_the_owner_in_app [pass]; tests/test_register_integrity_gaps.py::test_output_tax_in_ledger_equals_sum_of_completed_invoice_tax [pass] | Code: backend/core/tasks.py:nightly_invariants_task; backend/planwave/services.py:open_quarantine; backend/planwave/services.py:assert_books_clear; backend/reporting/gst_periods.py:soft_close_period | Run: pytest on SQLite 2026-10-05 (Postgres-only tests skipped) | AE12: =IFERROR(INDEX('Task Register'!$AJ$2:$AJ$771,MATCH(B12,'Task Register'!$A$2:$A$771,0)),"") -> Built - partial | AF12: =IFERROR(INDEX('Task Register'!$AU$2:$AU$771,MATCH(B12,'Task Register'!$A$2:$A$771,0)),"") -> Partial | AG12: feature | AI12: 22 | AJ12: S-0561
A13: WI-006 | B13: S-0568 | C13: Database foreign key cascade deletion defense and soft-delete enforcement | D13: 1 | E13: MVP | F13: Audit & integrity | G13: Backend | H13: is_deleted on Customer, Supplier, Product, Warehouse and PriceList; restore by Owner/Admin; ledger accounts keep their guard; transactions are cancelled, never soft-deleted. Cascades onto transactional rows become PROTECT; existing child rows untouched; an orphan report is produced before the migration. | I13: Pass: Soft-deleted masters vanish from lists, reports and search and Owner/Admin can restore them with history intact. Rejecting case: Hard delete of a master that has transactions raises; deleting a parent no longer cascades onto transactional rows. Done means: tests for the touched apps pass on Postgres 17 with lint and type checks clean and any strict xfail for the item removed; the reviewer (not the author) signs; register_sync.py scores the test and the register row reads Built - tested / Pass; the full suite runs nightly and at the wave gate. | J13: backend/tests/test_plan_s_0568.py | L13: Agent 1 | M13: 4 | N13: =ROUNDUP(M13*(1+'Plan guide'!$B$6),0) -> 5 | O13: 46318 | P13: 46324 | Q13: Done | R13: In progress | S13: In progress | T13: Not started | U13: Not started | V13: =IF(COUNTIF(Q13:U13,"Blocked")>0,"Blocked",IF(COUNTIF(Q13:U13,"Done")+COUNTIF(Q13:U13,"N/A")=5,"Done",IF(COUNTIF(Q13:U13,"Done")+COUNTIF(Q13:U13,"In progress")>0,"In progress","Not started"))) -> In progress | W13: =IF(5-COUNTIF(Q13:U13,"N/A")=0,1,COUNTIF(Q13:U13,"Done")/(5-COUNTIF(Q13:U13,"N/A"))) -> 0.2 | Z13: =IF(V13="Done",IF(Y13="",0,MAX(0,Y13-P13)),MAX(0,TODAY()-P13)) -> 0 | AA13: =IF(V13="Done","Done",IF(V13="Blocked","Red",IF(Z13>0,"Red",IF(AND(O13<=TODAY(),P13-TODAY()<=3,W13<0.5),"Amber","Green")))) -> Green | AB13: Gap: Soft delete exists on Customer, Supplier, Product, Warehouse, PriceList and sales FKs are PROTECT, but some child FKs to Customer/Product/Warehouse remain CASCADE (payments dunning/portal/promise, warehouse reorder/running costs). orphan_report and its management command have no test. Restore permission is Owner/Manager/Accountant, not Owner/Admin only. Only Customer is tested for soft-delete and restore. | AC13: uncommitted working tree | AD13: Tests: tests/test_planwave_remaining.py::test_soft_deleted_customer_hides_and_hard_delete_is_refused [pass]; tests/test_planwave_finish.py::test_restore_brings_a_customer_back [pass] | Code: backend/core/models.py:SoftDeleteFields; backend/planwave/finish.py:restore_master; backend/planwave/finish.py:orphan_report; backend/planwave/views.py:RestoreMasterView | Run: pytest on SQLite 2026-10-05 (Postgres-only tests skipped) | AE13: =IFERROR(INDEX('Task Register'!$AJ$2:$AJ$771,MATCH(B13,'Task Register'!$A$2:$A$771,0)),"") -> Built - partial | AF13: =IFERROR(INDEX('Task Register'!$AU$2:$AU$771,MATCH(B13,'Task Register'!$A$2:$A$771,0)),"") -> Partial | AG13: feature | AI13: 23 | AJ13: S-0568
A14: WI-007 | B14: S-0570 | C14: Automated continuous WAL archiving and daily encrypted PostgreSQL pg_dump snapshot | D14: 1 | E14: MVP | F14: Platform & reliability | G14: Infra | H14: Provider-specific design after DEC-HOST: WAL archiving and point-in-time recovery plus the daily encrypted dump, RPO 5 min and RTO 1 h by default, keys held in the provider key service. Restore drill into a non-production copy, timed. | I14: Pass: Timed restore drill reaches a chosen target time within the RTO; the encrypted dump restores. Rejecting case: Restore with the wrong key fails; a gap in archived WAL raises an alert. Done means: the drill is executed on a non-production copy and its timings and steps are attached; the reviewer signs. | J14: drill log in qos/evidence/ (restore or alert drill) | K14: WI-069 | L14: Agent 2 | M14: 3 | N14: =ROUNDUP(M14*(1+'Plan guide'!$B$6),0) -> 4 | O14: 46318 | P14: 46323 | Q14: Done | R14: In progress | S14: Not started | T14: Not started | U14: Not started | V14: =IF(COUNTIF(Q14:U14,"Blocked")>0,"Blocked",IF(COUNTIF(Q14:U14,"Done")+COUNTIF(Q14:U14,"N/A")=5,"Done",IF(COUNTIF(Q14:U14,"Done")+COUNTIF(Q14:U14,"In progress")>0,"In progress","Not started"))) -> In progress | W14: =IF(5-COUNTIF(Q14:U14,"N/A")=0,1,COUNTIF(Q14:U14,"Done")/(5-COUNTIF(Q14:U14,"N/A"))) -> 0.2 | Z14: =IF(V14="Done",IF(Y14="",0,MAX(0,Y14-P14)),MAX(0,TODAY()-P14)) -> 0 | AA14: =IF(V14="Done","Done",IF(V14="Blocked","Red",IF(Z14>0,"Red",IF(AND(O14<=TODAY(),P14-TODAY()<=3,W14<0.5),"Amber","Green")))) -> Green | AB14: Gap: No WAL archiving or point-in-time recovery, no RPO 5 min / RTO 1 h configuration, no provider key-service integration (GPG/age recipient only), and no timed restore drill log in qos/evidence. | AC14: uncommitted working tree | AD14: Code: scripts/backup.sh; scripts/restore_drill.sh; .github/workflows/backup-restore-drill.yml | Run: pytest on SQLite 2026-10-05 (Postgres-only tests skipped) | AE14: =IFERROR(INDEX('Task Register'!$AJ$2:$AJ$771,MATCH(B14,'Task Register'!$A$2:$A$771,0)),"") -> Built - partial | AF14: =IFERROR(INDEX('Task Register'!$AU$2:$AU$771,MATCH(B14,'Task Register'!$A$2:$A$771,0)),"") -> Partial | AG14: infra drill | AI14: 6 | AJ14: S-0570
